Workbook

Sheet Next process XÓA materil,khắc
A1: f | B1: ChildItemCode | C1: ItemCode | E1: =COUNTIF(B:B,B1) -> 1
B2: 1AP4LP1525JPZA | C2: 1AP0LP1525JPZA | D2: =VLOOKUP(B2,'Rom dung chung'!$C:$C,1,0) -> #N/A | E2: =COUNTIF(B:B,B2) -> 1
B3: 1RE1D820V4 | C3: 1RH1D820V4 | D3: =VLOOKUP(B3,'Rom dung chung'!$C:$C,1,0) -> #N/A | E3: =COUNTIF(B:B,B3) -> 1
B4: 1RH1D820V4 | C4: 1CM1D820V4 | D4: =VLOOKUP(B4,'Rom dung chung'!$C:$C,1,0) -> #N/A | E4: =COUNTIF(B:B,B4) -> 1
B5: 1CM1D820V4 | C5: 1AP1D820V4 | D5: =VLOOKUP(B5,'Rom dung chung'!$C:$C,1,0) -> #N/A | E5: =COUNTIF(B:B,B5) -> 1
B6: 1RE1D921CV4 | C6: 1RH1D921CV4 | D6: =VLOOKUP(B6,'Rom dung chung'!$C:$C,1,0) -> #N/A | E6: =COUNTIF(B:B,B6) -> 1
B7: 1RH1D921CV4 | C7: 1AP1D921CV4 | D7: =VLOOKUP(B7,'Rom dung chung'!$C:$C,1,0) -> #N/A | E7: =COUNTIF(B:B,B7) -> 1
B8: 1RE2F081A | C8: 1AP1F081A | D8: =VLOOKUP(B8,'Rom dung chung'!$C:$C,1,0) -> #N/A | E8: =COUNTIF(B:B,B8) -> 1
B9: 1CM1F220V4 | C9: 1RE2F220V4 | D9: =VLOOKUP(B9,'Rom dung chung'!$C:$C,1,0) -> #N/A | E9: =COUNTIF(B:B,B9) -> 1
B10: 1RE2F220V4 | C10: 1RH1F220V4 | D10: =VLOOKUP(B10,'Rom dung chung'!$C:$C,1,0) -> #N/A | E10: =COUNTIF(B:B,B10) -> 1
B11: 1RH1F220V4 | C11: 1AP1F220V4 | D11: =VLOOKUP(B11,'Rom dung chung'!$C:$C,1,0) -> #N/A | E11: =COUNTIF(B:B,B11) -> 1
B12: 1CM1F222V4 | C12: 1RE2F222V4 | D12: =VLOOKUP(B12,'Rom dung chung'!$C:$C,1,0) -> #N/A | E12: =COUNTIF(B:B,B12) -> 1
B13: 1RE2F222V4 | C13: 1AP1F222V4 | D13: =VLOOKUP(B13,'Rom dung chung'!$C:$C,1,0) -> #N/A | E13: =COUNTIF(B:B,B13) -> 1
... B4345: 1AE1ARBPC1A06880 | C4345: 1RH1ARBPC1A06880 | D4345: =VLOOKUP(B4345,'Rom dung chung'!$C:$C,1,0) -> #N/A | E4345: =COUNTIF(B:B,B4345) -> 1
B4346: 1RH1H603Y3J90BP-FE | C4346: 1CM1H603Y3J90BP-FE | E4346: =COUNTIF(B:B,B4346) -> 1
B4347: 1TE1H603Y3J90BP-FE | C4347: 1RH1H603Y3J90BP-FE | E4347: =COUNTIF(B:B,B4347) -> 1
B4348: 1AE1H603Y3J90BP-FE | C4348: 1TE1H603Y3J90BP-FE | E4348: =COUNTIF(B:B,B4348) -> 1
B4349: 1HT1H603Y3J90BP-FE | C4349: 1AE1H603Y3J90BP-FE | E4349: =COUNTIF(B:B,B4349) -> 1
B4350: 1RH1ARBPC1A03940 | C4350: 1CM1ARBPC1A03942 | E4350: =COUNTIF(B:B,B4350) -> 1
B4351: 1RH1ARBPC1A10775 | C4351: 1CM1ARBPC1A10775 | E4351: =COUNTIF(B:B,B4351) -> 1
B4352: 1AE1ARBPC1A10775 | C4352: 1RH1ARBPC1A10775 | E4352: =COUNTIF(B:B,B4352) -> 1
B4353: 1RE1ARBPC1A10775 | C4353: 1AE1ARBPC1A10775 | E4353: =COUNTIF(B:B,B4353) -> 1
B4354: 1RH1ARBPC1A10784 | C4354: 1CM1ARBPC1A10784 | E4354: =COUNTIF(B:B,B4354) -> 1
B4355: 1AE1ARBPC1A10784 | C4355: 1RH1ARBPC1A10784 | E4355: =COUNTIF(B:B,B4355) -> 1
B4356: 1RE1ARBPC1A10784 | C4356: 1AE1ARBPC1A10784 | E4356: =COUNTIF(B:B,B4356) -> 1
B4357: 1RH1ARBPC1A11952 | C4357: 1CM1ARBPC1A11952 | E4357: =COUNTIF(B:B,B4357) -> 1
... B4470: 1RH1ARBPC1A07320 | C4470: 1CM1ARBPC1A07320 | E4470: =COUNTIF(B:B,B4470) -> 1
B4471: 1AE1ARBPC1A07320 | C4471: 1RH1ARBPC1A07320
B4472: 1RH1ARBPC1A07330 | C4472: 1CM1ARBPC1A07330
B4473: 1AE1ARBPC1A07330 | C4473: 1RH1ARBPC1A07330
B4474: 1CM1ARBP0DA0072A-1 | C4474: 1RH1ARBP0DA0072A-1
B4475: 1RE1ARBP0DA0072A-1 | C4475: 1CM1ARBP0DA0072A-1
B4476: 1AE1ARBPC1A09850 | C4476: 1RH1ARBPC1A09850
B4477: 1RE1ARBPC1A09850 | C4477: 1AE1ARBPC1A09850
B4478: 1CM1ART002T92011 | C4478: 1RH1ART002T92011
B4479: 1RE1ART002T92011 | C4479: 1CM1ART002T92011
B4480: 1CM1ART002T93680 | C4480: 1RH1ART002T93680
B4481: 1RE1ART002T93680 | C4481: 1CM1ART002T93680
B4482: 1CM1ART002T93690 | C4482: 1RH1ART002T93690
... B4945: 1RE1ARBPC1A09213 | C4945: 1AE1ARBPC1A09213

Sheet Previous process
B1: ItemCode | C1: ChildItemCode
B2: JS_E_ITEMCOMPOSITION.ITEMCODE,JS_E_ITEMCOMPOSITION_E3.ITEMCODE | C2: JS_E_ITEMCOMPOSITION.CHILDITEMCODE,JS_E_ITEMCOMPOSITION_E3.CHILDITEMCODE
B3: 0,0,0,1,0005, | C3: 0,0,0,1,0004,
B4: 1AP4LP1525JPZA | C4: Material
B5: 1AP0LP1525JPZA | C5: 1AP4LP1525JPZA
B6: 1RE1D820V4 | C6: Material
B7: 1RH1D820V4 | C7: 1RE1D820V4
B8: 1CM1D820V4 | C8: 1RH1D820V4
B9: 1AP1D820V4 | C9: 1CM1D820V4
B10: 1RE1D921CV4 | C10: Material
B11: 1RH1D921CV4 | C11: 1RE1D921CV4
B12: 1AP1D921CV4 | C12: 1RH1D921CV4
... B5254: 1RE1A607B3J8AP2-P2 | C5254: A6644-3J80
B5255: 1RE2A608B-3J8A-P2 | C5255: 1RE1A608B-3J8A-P2 | H5255: 1RE1SRB20YSZB-V4
B5256: 1RE1A608B-3J8A-P2 | C5256: A6746-3J80 | H5256: PGLB1751TA-WK
B5257: 1RE1SZ200P-V4 | C5257: PGLB2179ZA-4V | H5257: Material
B5258: PGLB2179ZA-4V | C5258: Material | H5258: Material
B5259: 1RE2CC411BP | C5259: 1RE1CC411BP
B5260: 1RE1CC411BP | C5260: PULB1028ZA/V1
B5261: 1RE1CC411BP | C5261: 1VJ1CC411BPBB1
B5262: 1RE1CC411BP | C5262: 3VJ1CC411BPDSP1
B5263: 1VJ1CC411BPBB1 | C5263: Material
B5264: 3VJ1CC411BPDSP1 | C5264: Material | H5264: 1RE1SRC14YSZB-V4
B5265: PULB1028ZA/V1 | C5265: Material | H5265: PGLB1751TA-WK
B5266: 1RE2CC412BP | C5266: 1RE1CC412BP | H5266: Material
B5267: 1RE1CC412BP | C5267: PULB1028ZA/V1
B5268: 1RE1CC412BP | C5268: 3VJ1CC411BPDSP1
B5269: 1RE1CC412BP | C5269: 4VJ1CC412BPBB2
B5270: 1RE1CC412BP | C5270: 5VJ1CC412BPDSP2
B5271: 1RE1CC412BP | C5271: 1VJ1CC411BPBB1
B5272: 4VJ1CC412BPBB2 | C5272: Material
B5273: 5VJ1CC412BPDSP2 | C5273: Material
B5274: 2RE2CC411BP | C5274: 2RE1CC411BP
B5275: 2RE1CC411BP | C5275: PGLB1462YA-GL
B5276: 2RE1CC411BP | C5276: 2VJ1CC411BPUNI1
B5277: 2RE1CC411BP | C5277: 2VJ2CC411BPUNI2
B5278: 2VJ1CC411BPUNI1 | C5278: Material
... B7952: 1RE1ARBPC1A09213 | C7952: Material

Sheet PCB barcode
B1: CompleteItemCode | C1: ChildItemCode | D1: ItemCode
B2: 1RH1LP2577ZA | C2: PNLB2110ZB-WK | D2: 1RE1LP2577ZA
B3: 1RH1LP2578ZA | C3: PNLB2110ZB-WK | D3: 1RE1LP2578ZA
B4: 1RH1LP2579ZA | C4: PNLB2110ZB-WK | D4: 1RE1LP2579ZA
B5: 1RH1LP2581ZA | C5: PNLB2110ZB-WK | D5: 1RE1LP2581ZA
B6: 1RH1LP2594ZA | C6: PNLB2110ZB-WK | D6: 1RE1LP2594ZA
B7: 1RE2LPS2087MZA | C7: PNLB2516ZA-GW | D7: 1RE1LPS2087MZA
B8: 1CM1LPS2087PZA | C8: PNLB2521ZA-GW | D8: 1RE1LPS2087PZA
B9: 1CM1LPS2087SZA | C9: PNLB2519ZA-PN | D9: 1CM1LPS2087SZA
B10: 1RH1NS5162SX | C10: PNLB2270YA-LV | D10: 1RE1NS5162SX
B11: 1RH1NS5162X | C11: PNLB2270YA-LV | D11: 1RE1NS5162X
B12: 1RH1NS5170SX | C12: PNLB2265ZA-LV | D12: 1RE1NS5170SX
... B470: PGLB1463YA-6H | C470: PGLB1463YA-6H | D470: 3AP1CC411AP-V4
B471: PULB1030ZA-XM | C471: PULB1030ZA-XM | D471: Check lại next sang model nào FA | E471: 3AP1CC411BZA 3AP1CC411BPZA
B472: 1RE2PS200YSZB-R2 | C472: PGLB2156YA-XM | D472: 1RE1PS200YSZB-R2
B473: 1AE1A603M-3J0A | C473: A6403-3821 | D473: 1AE1A603M-3J0A
B474: 1AE1A603M-3J3A | C474: A6403-3D00 | D474: 1AE1A603M-3J3A
B475: 1AE1A608B3G1AEU | C475: A67463G10EU | D475: 1HT1A608B3G1AEU
B476: 1AE1A608B3H7AAP | C476: A67463G10EU | D476: 1HT1A608B3H7AAP
B477: 1AE1A608B3H9AAP | C477: A67463G10EU | D477: 1HT1A608B3H9AAP
B478: 1CM1A603L-3J0A | C478: A6260-3J00 | D478: 1AE1A603L-3J0A
B479: 1CM1A603L-3J2A | C479: A6260-3J00 | D479: 1AE1A603L-3J2A
B480: 1CM1A603L-3J3A | C480: A6260-3J30 | D480: 1AE1A603L-3J3A
B481: 1CM1A603L-3K50 | C481: A6260-3J00 | D481: 1AE1A603L-3K50
B482: 1CM1A603L3F0AAP | C482: A62603E61AP | D482: 1AE1A603L3F0AAP
B483: 1CM1A603L3F9ABP | C483: A62603E61AP | D483: 1AE1A603L3F9ABP
... B895: 1RE2H685Q3K20AP | C895: H6575-3K20 | D895: 1RE1H685Q3K20AP

Sheet Rom dung chung
B1: CompleteItemCode | C1: ChildItemCode | D1: ItemCode
B2: 1RH1ARBPC1A05383 | C2: 1AE1ARBPC1A04072 | D2: 1RH1ARBPC1A05383 | E2: =COUNTIF(C2:C79,C2) -> 2
B3: 1CM1ARBPC1A04075 | C3: 1AE1ARBPC1A04072 | D3: 1RH1ARBPC1A04075 | E3: =COUNTIF(C3:C79,C3) -> 1
B4: 1RH1ARBPC1A05244 | C4: 1AE1ARBPC1A05242 | D4: 1RH1ARBPC1A05244 | E4: =COUNTIF(C4:C79,C4) -> 1
B5: 1RE2H685Q-3K20PP2 | C5: 1VI1H685Q-3K20PP2 | D5: 1RE1H685Q-3K20PP2 | E5: =COUNTIF(C5:C79,C5) -> 2
B6: 1RE2H685Q-3K20-P2 | C6: 1VI1H685Q-3K20PP2 | D6: 1RE1H685Q-3K20-P2 | E6: =COUNTIF(C6:C79,C6) -> 1
B7: 1RE2LPN1028XM-S1 | C7: 1VI1LPN1058XM-S1 | D7: 1RE1LPN1028XM-S1 | E7: =COUNTIF(C7:C79,C7) -> 1
B8: 1RE2LPN1028YM-S1 | C8: 1VI1LPN1058YM-S1 | D8: 1RE1LPN1028YM-S1 | E8: =COUNTIF(C8:C79,C8) -> 1
B9: PNLPPU100NMZA-V4 | C9: 1VI1LPPU100NMZA | D9: 1RE1LPPU100NMZA | E9: =COUNTIF(C9:C79,C9) -> 1
B10: 1RE2LPS1027CMZA | C10: 1VI1LPS1057CMZA | D10: 1RE1LPS1027CMZA | E10: =COUNTIF(C10:C79,C10) -> 3
B11: 1RE2LPS1057CMZA | C11: 1VI1LPS1057CMZA | D11: 1RE1LPS1057CMZA | E11: =COUNTIF(C11:C79,C11) -> 2
B12: 1RE2LPSL1056MZA | C12: 1VI1LPS1057CMZA | D12: 1RE1LPSL1056MZA | E12: =COUNTIF(C12:C79,C12) -> 1
B13: 1RE2LPS1028YMZA | C13: 1VI1LPS1058YMZA | D13: 1RE1LPS1028YMZA | E13: =COUNTIF(C13:C79,C13) -> 1
B14: 1RE2LPS8127MZA | C14: 1VI1LPS8147MZA | D14: 1RE1LPS8127MZA | E14: =COUNTIF(C14:C79,C14) -> 4
B15: 1RE2LPS8147MZA | C15: 1VI1LPS8147MZA | D15: 1RE1LPS8147MZA | E15: =COUNTIF(C15:C79,C15) -> 3
B16: 1RE2LPS8120MZA | C16: 1VI1LPS8147MZA | D16: 1RE1LPS8120MZA | E16: =COUNTIF(C16:C79,C16) -> 2
B17: 1RE2LPS8130MZA | C17: 1VI1LPS8147MZA | D17: 1RE1LPS8130MZA | E17: =COUNTIF(C17:C79,C17) -> 1
B18: 1RE2LPS8127ZVMZA | C18: 1VI1LPS8147ZVMZA | D18: 1RE1LPS8127ZVMZA | E18: =COUNTIF(C18:C79,C18) -> 1
B19: 1RE2LPSL3056M-S1 | C19: 1VI1LPSL3066M-S1 | D19: 1RE1LPSL3056M-S1 | E19: =COUNTIF(C19:C79,C19) -> 1
B20: 1RE2TP4NH1250BN | C20: 1VI1TVRU455AB | D20: 1RE2TP4NH1250BN | E20: =COUNTIF(C20:C79,C20) -> 6
B21: 1RE2TP4NH1250BP | C21: 1VI1TVRU455AB | D21: 1RE2TP4NH1250BP | E21: =COUNTIF(C21:C79,C21) -> 5
B22: 1RE2TP4NH1250EN | C22: 1VI1TVRU455AB | D22: 1RE2TP4NH1250EN | E22: =COUNTIF(C22:C79,C22) -> 4
B23: 1RE2TP4NH1250EP | C23: 1VI1TVRU455AB | D23: 1RE2TP4NH1250EP | E23: =COUNTIF(C23:C80,C23) -> 3
B24: 1RE2TP4NH1258BX | C24: 1VI1TVRU455AB | D24: 1RE2TP4NH1258BX | E24: =COUNTIF(C24:C81,C24) -> 2
B25: 1RE2TP4NH1258EX | C25: 1VI1TVRU455AB | D25: 1RE2TP4NH1258EX | E25: =COUNTIF(C25:C82,C25) -> 1
B26: 1RE2TP4NH1250BM | C26: 1VI1TVRU469AB | D26: 1RE2TP4NH1250BM | E26: =COUNTIF(C26:C83,C26) -> 3
B27: 1RE2TP4NH1250EM | C27: 1VI1TVRU469AB | D27: 1RE2TP4NH1250EM | E27: =COUNTIF(C27:C84,C27) -> 2
B28: 1RE2TP3MH1250BM-1 | C28: 1VI1TVRU469AB | D28: 1RE2TP3MH1250BM-1 | E28: =COUNTIF(C28:C85,C28) -> 1
B29: 1RE2TP4NH1266EC-1 | C29: 1VI1TVRU484 | D29: 1RE2TP4NH1266EC-1 | E29: =COUNTIF(C29:C86,C29) -> 4
B30: 1RE2TP4NH1266ED-1 | C30: 1VI1TVRU484 | D30: 1RE2TP4NH1266ED-1 | E30: =COUNTIF(C30:C87,C30) -> 3
B31: 1RE2TP4NH1266EE-1 | C31: 1VI1TVRU484 | D31: 1RE2TP4NH1266EE-1 | E31: =COUNTIF(C31:C88,C31) -> 2
B32: 1RE2TP4NH1266EF-1 | C32: 1VI1TVRU484 | D32: 1RE2TP4NH1266EF-1 | E32: =COUNTIF(C32:C89,C32) -> 1
B33: 1RE2TP4NH1266EA-1 | C33: 1VI1TVRU484AA | D33: 1RE2TP4NH1266EA-1 | E33: =COUNTIF(C33:C90,C33) -> 5
B34: 1RE2TP4NH1266EC-1 | C34: 1VI1TVRU484AA | D34: 1RE2TP4NH1266EC-1 | E34: =COUNTIF(C34:C90,C34) -> 4
B35: 1RE2TP4NH1266EE-1 | C35: 1VI1TVRU484AA | D35: 1RE2TP4NH1266EE-1 | E35: =COUNTIF(C35:C91,C35) -> 3
B36: 1RE2TP4NH1266ED-1 | C36: 1VI1TVRU484AA | D36: 1RE2TP4NH1266ED-1 | E36: =COUNTIF(C36:C92,C36) -> 2
B37: 1RE2TP4NH1266EF-1 | C37: 1VI1TVRU484AA | D37: 1RE2TP4NH1266EF-1 | E37: =COUNTIF(C37:C93,C37) -> 1
B38: 1RE2H685Q-3K20PP2 | C38: 1VI2H685Q-3K20PP2 | D38: 1RE1H685Q-3K20PP2 | E38: =COUNTIF(C38:C95,C38) -> 2
B39: 1RE2H685Q-3K20-P2 | C39: 1VI2H685Q-3K20PP2 | D39: 1RE1H685Q-3K20-P2 | E39: =COUNTIF(C39:C96,C39) -> 1
B40: 1RE2CC412APYSZB-V4 | C40: 1VJ1CC411APBB1-V4 | D40: 1RE1CC412APYSZB-V4 | E40: =COUNTIF(C40:C97,C40) -> 2
...

Sheet IOT
A1: ItemCode | C1: 1 | D1: Điểm cắm | E1: BF-Production Version | F1: BF-Plant | G1: TF-Action | H1: TF-Movement Type | I1: TF-From Location | J1: TF-To Location | K1: TF-Action | L1: QUA Đâu
E2: Kho mình | F2: cat | I2: Kho nhận | J2: Kho chuyển
A3: 1AP4LP1525JPZA | B3: SMT | C3: =COUNTIF(A3:A6460,A3) -> 1 | D3: =VLOOKUP(A3,[1]Sheet1!$A:$B,2,0) -> 9 | E3: 2210 | F3: VC01 | G3: Auto | H3: 311 | I3: 2210 | J3: 2310 | K3: VC01
A4: 1AP0LP1525JPZA | B4: DIP | C4: =COUNTIF(A4:A6461,A4) -> 1 | D4: =VLOOKUP(A4,[1]Sheet1!$A:$B,2,0) -> #N/A | E4: 2210 | F4: VC01 | G4: Auto | H4: 311 | I4: 2210 | J4: 2310 | K4: VC01
A5: 1RE1D820V4 | B5: SMT | C5: =COUNTIF(A5:A6462,A5) -> 1 | D5: =VLOOKUP(A5,[1]Sheet1!$A:$B,2,0) -> 304
A6: 1RH1D820V4 | B6: SMT | C6: =COUNTIF(A6:A6463,A6) -> 1 | D6: =VLOOKUP(A6,[1]Sheet1!$A:$B,2,0) -> 67
A7: 1CM1D820V4 | B7: SMT | C7: =COUNTIF(A7:A6464,A7) -> 1 | D7: =VLOOKUP(A7,[1]Sheet1!$A:$B,2,0) -> 381 | E7: 2210 | F7: VC01 | G7: Auto | H7: 311 | I7: 2210 | J7: 2310 | K7: VC01
A8: 1AP1D820V4 | B8: DIP | C8: =COUNTIF(A8:A6465,A8) -> 1 | D8: =VLOOKUP(A8,[1]Sheet1!$A:$B,2,0) -> #N/A | E8: 2210 | F8: VC01 | G8: Auto | H8: 311 | I8: 2210 | J8: 2310 | K8: VC01
A9: 1RE1D921CV4 | B9: SMT | C9: =COUNTIF(A9:A6466,A9) -> 1 | D9: =VLOOKUP(A9,[1]Sheet1!$A:$B,2,0) -> 271
A10: 1RH1D921CV4 | B10: SMT | C10: =COUNTIF(A10:A6467,A10) -> 1 | D10: =VLOOKUP(A10,[1]Sheet1!$A:$B,2,0) -> 50 | E10: 2210 | F10: VC01 | G10: Auto | H10: 311 | I10: 2210 | J10: 2310 | K10: VC01
A11: 1AP1D921CV4 | B11: DIP | C11: =COUNTIF(A11:A6468,A11) -> 1 | D11: =VLOOKUP(A11,[1]Sheet1!$A:$B,2,0) -> #N/A | E11: 2210 | F11: VC01 | G11: Auto | H11: 311 | I11: 2210 | J11: 2310 | K11: VC01
A12: 1RE2F081A | B12: SMT | C12: =COUNTIF(A12:A6469,A12) -> 1 | D12: =VLOOKUP(A12,[1]Sheet1!$A:$B,2,0) -> 157 | E12: 2210 | F12: VC01 | G12: Auto | H12: 311 | I12: 2210 | J12: 2310 | K12: VC01
A13: 1AP1F081A | B13: DIP | C13: =COUNTIF(A13:A6470,A13) -> 1 | D13: =VLOOKUP(A13,[1]Sheet1!$A:$B,2,0) -> #N/A | E13: 2210 | F13: VC01 | G13: Auto | H13: 311 | I13: 2210 | J13: 2310 | K13: VC01
A14: 1AP1F082 | B14: DIP | C14: =COUNTIF(A14:A6471,A14) -> 1 | D14: =VLOOKUP(A14,[1]Sheet1!$A:$B,2,0) -> #N/A | E14: 2210 | F14: VC01 | G14: Auto | H14: 311 | I14: 2210 | J14: 2310 | K14: VC01
A15: 1CM1F220V4 | B15: SMT | C15: =COUNTIF(A15:A6472,A15) -> 1 | D15: =VLOOKUP(A15,[1]Sheet1!$A:$B,2,0) -> 160
A16: 1RE2F220V4 | B16: SMT | C16: =COUNTIF(A16:A6473,A16) -> 1 | D16: =VLOOKUP(A16,[1]Sheet1!$A:$B,2,0) -> 141
A17: 1RH1F220V4 | B17: SMT | C17: =COUNTIF(A17:A6474,A17) -> 1 | D17: =VLOOKUP(A17,[1]Sheet1!$A:$B,2,0) -> 25 | E17: 2210 | F17: VC01 | G17: Auto | H17: 311 | I17: 2210 | J17: 2310 | K17: VC01
A18: 1AP1F220V4 | B18: DIP | C18: =COUNTIF(A18:A6475,A18) -> 1 | D18: =VLOOKUP(A18,[1]Sheet1!$A:$B,2,0) -> #N/A | E18: 2210 | F18: VC01 | G18: Auto | H18: 311 | I18: 2210 | J18: 2310 | K18: VC01
A19: 1CM1F222V4 | B19: SMT | C19: =COUNTIF(A19:A6475,A19) -> 1 | D19: =VLOOKUP(A19,[1]Sheet1!$A:$B,2,0) -> 120
A20: 1RE2F222V4 | B20: SMT | C20: =COUNTIF(A20:A6476,A20) -> 1 | D20: =VLOOKUP(A20,[1]Sheet1!$A:$B,2,0) -> 212 | E20: 2210 | F20: VC01 | G20: Auto | H20: 311 | I20: 2210 | J20: 2310 | K20: VC01
A21: 1AP1F222V4 | B21: DIP | C21: =COUNTIF(A21:A6477,A21) -> 1 | D21: =VLOOKUP(A21,[1]Sheet1!$A:$B,2,0) -> #N/A | E21: 2210 | F21: VC01 | G21: Auto | H21: 311 | I21: 2210 | J21: 2310 | K21: VC01
A22: 1RE1F231V4 | B22: SMT | C22: =COUNTIF(A22:A6478,A22) -> 1 | D22: =VLOOKUP(A22,[1]Sheet1!$A:$B,2,0) -> 56
A23: 1RE2F231V4 | B23: SMT | C23: =COUNTIF(A23:A6479,A23) -> 1 | D23: =VLOOKUP(A23,[1]Sheet1!$A:$B,2,0) -> 196
A24: 1RH1F231V4 | B24: SMT | C24: =COUNTIF(A24:A6480,A24) -> 1 | D24: =VLOOKUP(A24,[1]Sheet1!$A:$B,2,0) -> 8 | E24: 2210 | F24: VC01 | G24: Auto | H24: 311 | I24: 2210 | J24: 2310 | K24: VC01
A25: 1AP1F231V4 | B25: DIP | C25: =COUNTIF(A25:A6481,A25) -> 1 | D25: =VLOOKUP(A25,[1]Sheet1!$A:$B,2,0) -> #N/A | E25: 2210 | F25: VC01 | G25: Auto | H25: 311 | I25: 2210 | J25: 2310 | K25: VC01
A26: 1AP1LC1024ZA | B26: DIP | C26: =COUNTIF(A26:A6482,A26) -> 1 | D26: =VLOOKUP(A26,[1]Sheet1!$A:$B,2,0) -> #N/A | E26: 2210 | F26: VC01 | G26: Auto | H26: 311 | I26: 2210 | J26: 2310 | K26: VC01
A27: 1VJ1LP2288ZA | B27: SMT | C27: =COUNTIF(A27:A6482,A27) -> 1 | D27: =VLOOKUP(A27,[1]Sheet1!$A:$B,2,0) -> #N/A
A28: 1RE1LP2288ZA | B28: SMT | C28: =COUNTIF(A28:A6482,A28) -> 1 | D28: =VLOOKUP(A28,[1]Sheet1!$A:$B,2,0) -> 265
A29: 1RE2LP2288ZA | B29: SMT | C29: =COUNTIF(A29:A6482,A29) -> 1 | D29: =VLOOKUP(A29,[1]Sheet1!$A:$B,2,0) -> 460
A30: 1RH1LP2288ZA | B30: SMT | C30: =COUNTIF(A30:A6482,A30) -> 1 | D30: =VLOOKUP(A30,[1]Sheet1!$A:$B,2,0) -> 8 | E30: 2210 | F30: VC01 | G30: Auto | H30: 311 | I30: 2210 | J30: 2220 | K30: VC01
A31: 1AP1LP2288ZA | B31: DIP | C31: =COUNTIF(A31:A6483,A31) -> 1 | D31: =VLOOKUP(A31,[1]Sheet1!$A:$B,2,0) -> #N/A | E31: 2210 | F31: VC01 | G31: Auto | H31: 311 | I31: 2210 | J31: 2220 | K31: VC01
A32: 1AP1LP2289ZA | B32: DIP | C32: =COUNTIF(A32:A6484,A32) -> 1 | D32: =VLOOKUP(A32,[1]Sheet1!$A:$B,2,0) -> #N/A | E32: 2210 | F32: VC01 | G32: Auto | H32: 311 | I32: 2210 | J32: 2310 | K32: VC01
A33: 1VI1LP2534ZA | B33: SMT | C33: =COUNTIF(A33:A6485,A33) -> 1 | D33: =VLOOKUP(A33,[1]Sheet1!$A:$B,2,0) -> #N/A
A34: 1RE1LP2534ZA | B34: SMT | C34: =COUNTIF(A34:A6486,A34) -> 1 | D34: =VLOOKUP(A34,[1]Sheet1!$A:$B,2,0) -> 223
A35: 1RE2LP2534ZA | B35: SMT | C35: =COUNTIF(A35:A6487,A35) -> 1 | D35: =VLOOKUP(A35,[1]Sheet1!$A:$B,2,0) -> 228 | E35: 2210 | F35: VC01 | G35: Auto | H35: 311 | I35: 2210 | J35: 2220 | K35: VC01
A36: 1AP1LP2534ZA | B36: DIP | C36: =COUNTIF(A36:A6488,A36) -> 1 | D36: =VLOOKUP(A36,[1]Sheet1!$A:$B,2,0) -> #N/A | E36: 2210 | F36: VC01 | G36: Auto | H36: 311 | I36: 2210 | J36: 2220 | K36: VC01
A37: 1RE1LP2537ZA | B37: SMT | C37: =COUNTIF(A37:A6489,A37) -> 1 | D37: =VLOOKUP(A37,[1]Sheet1!$A:$B,2,0) -> 43 | E37: 2210 | F37: VC01 | G37: Auto | H37: 311 | I37: 2210 | J37: 2310 | K37: VC01
A38: 1AP1LP2537ZA | B38: DIP | C38: =COUNTIF(A38:A6490,A38) -> 1 | D38: =VLOOKUP(A38,[1]Sheet1!$A:$B,2,0) -> #N/A | E38: 2210 | F38: VC01 | G38: Auto | H38: 311 | I38: 2210 | J38: 2310 | K38: VC01
A39: 1VJ1LP2538ZA | B39: SMT | C39: =COUNTIF(A39:A6491,A39) -> 1 | D39: =VLOOKUP(A39,[1]Sheet1!$A:$B,2,0) -> #N/A
A40: 1RE1LP2538ZA | B40: SMT | C40: =COUNTIF(A40:A6492,A40) -> 1 | D40: =VLOOKUP(A40,[1]Sheet1!$A:$B,2,0) -> 484
...
